# 异常

```
当throw出现时，程序会直接跳转到catch处（一直向函数上层搜索catch块，如果没有catch则直接崩溃）

throw  处会创建或复制一个对象，throw上面所有变量进行了析构，然后在该处调用catch函数

class A{ public:  int x;  A(int a){x = a;}  };

try
{
	int condition = 2;  //根据condition，抛出不同类的对象
	if(1 == condition){ throw 1;}
	else if(2 == condition){throw  A(2); }
}catch(int i)//接收抛出的对象
{     cout<<i<<endl;
}catch(A &a)
{     cout<<a.x<<endl;
}catch(...)//接收前面catch没有枚举出的异常类型
{    cout<<"other exception"<<endl;
}
```
